<?xml version="1.0"?>
<robot name="ur5">

  <!-- ═══════════════════════════════════════════════════════════════
       LINKS — visual uses real UR5 meshes, collision uses primitives
  ═══════════════════════════════════════════════════════════════════ -->

  <link name="base_link">
    <visual>
      <origin rpy="0.0 0.0 3.141592653589793" xyz="0.0 0.0 0.0"/>
      <geometry><mesh filename="/opt/ros/humble/share/ur_description/meshes/ur5/visual/base.dae"/></geometry>
    </visual>
    <collision>
      <geometry><cylinder radius="0.075" length="0.05"/></geometry>
    </collision>
    <inertial>
      <mass value="4.0"/>
      <inertia ixx="0.01" ixy="0" ixz="0" iyy="0.01" iyz="0" izz="0.01"/>
    </inertial>
  </link>

  <link name="shoulder_link">
    <visual>
      <origin rpy="0.0 0.0 3.141592653589793" xyz="0.0 0.0 0.0"/>
      <geometry><mesh filename="/opt/ros/humble/share/ur_description/meshes/ur5/visual/shoulder.dae"/></geometry>
    </visual>
    <collision>
      <geometry><sphere radius="0.06"/></geometry>
    </collision>
    <inertial>
      <mass value="3.7"/>
      <inertia ixx="0.01" ixy="0" ixz="0" iyy="0.01" iyz="0" izz="0.01"/>
    </inertial>
  </link>

  <link name="upper_arm_link">
    <visual>
      <origin rpy="1.5707963267948966 0.0 -1.5707963267948966" xyz="0.0 0.0 0.13585"/>
      <geometry><mesh filename="/opt/ros/humble/share/ur_description/meshes/ur5/visual/upperarm.dae"/></geometry>
    </visual>
    <collision>
      <origin xyz="0 0 0.213" rpy="0 0 0"/>
      <geometry><cylinder radius="0.04" length="0.425"/></geometry>
    </collision>
    <inertial>
      <mass value="8.393"/>
      <inertia ixx="0.02" ixy="0" ixz="0" iyy="0.02" iyz="0" izz="0.01"/>
    </inertial>
  </link>

  <link name="forearm_link">
    <visual>
      <origin rpy="1.5707963267948966 0.0 -1.5707963267948966" xyz="0.0 0.0 0.0165"/>
      <geometry><mesh filename="/opt/ros/humble/share/ur_description/meshes/ur5/visual/forearm.dae"/></geometry>
    </visual>
    <collision>
      <origin xyz="0 0 0.196" rpy="0 0 0"/>
      <geometry><cylinder radius="0.03" length="0.392"/></geometry>
    </collision>
    <inertial>
      <mass value="2.275"/>
      <inertia ixx="0.01" ixy="0" ixz="0" iyy="0.01" iyz="0" izz="0.005"/>
    </inertial>
  </link>

  <link name="wrist_1_link">
    <visual>
      <origin rpy="1.5707963267948966 0.0 0.0" xyz="0.0 0.0 -0.093"/>
      <geometry><mesh filename="/opt/ros/humble/share/ur_description/meshes/ur5/visual/wrist1.dae"/></geometry>
    </visual>
    <collision>
      <geometry><sphere radius="0.035"/></geometry>
    </collision>
    <inertial>
      <mass value="1.219"/>
      <inertia ixx="0.005" ixy="0" ixz="0" iyy="0.005" iyz="0" izz="0.005"/>
    </inertial>
  </link>

  <link name="wrist_2_link">
    <visual>
      <origin rpy="0.0 0.0 0.0" xyz="0.0 0.0 -0.095"/>
      <geometry><mesh filename="/opt/ros/humble/share/ur_description/meshes/ur5/visual/wrist2.dae"/></geometry>
    </visual>
    <collision>
      <geometry><sphere radius="0.035"/></geometry>
    </collision>
    <inertial>
      <mass value="1.219"/>
      <inertia ixx="0.005" ixy="0" ixz="0" iyy="0.005" iyz="0" izz="0.005"/>
    </inertial>
  </link>

  <link name="wrist_3_link">
    <visual>
      <origin rpy="1.5707963267948966 0.0 0.0" xyz="0.0 0.0 -0.0818"/>
      <geometry><mesh filename="/opt/ros/humble/share/ur_description/meshes/ur5/visual/wrist3.dae"/></geometry>
    </visual>
    <collision>
      <geometry><sphere radius="0.03"/></geometry>
    </collision>
    <inertial>
      <mass value="0.1879"/>
      <inertia ixx="0.001" ixy="0" ixz="0" iyy="0.001" iyz="0" izz="0.001"/>
    </inertial>
  </link>

  <link name="tool0"/>

  <!-- ═══════════════════════════════════════════════════════════════
       JOINTS — using exact official UR5 kinematics from ur_description
  ═══════════════════════════════════════════════════════════════════ -->

  <joint name="shoulder_pan_joint" type="revolute">
    <parent link="base_link"/>
    <child link="shoulder_link"/>
    <origin xyz="0 0 0.089159" rpy="0 0 0"/>
    <axis xyz="0 0 1"/>
    <limit lower="-6.2832" upper="6.2832" effort="150.0" velocity="3.14159"/>
    <dynamics damping="0" friction="0"/>
  </joint>

  <joint name="shoulder_lift_joint" type="revolute">
    <parent link="shoulder_link"/>
    <child link="upper_arm_link"/>
    <origin xyz="0 0 0" rpy="1.570796327 0 0"/>
    <axis xyz="0 0 1"/>
    <limit lower="-6.2832" upper="6.2832" effort="150.0" velocity="3.14159"/>
    <dynamics damping="0" friction="0"/>
  </joint>

  <joint name="elbow_joint" type="revolute">
    <parent link="upper_arm_link"/>
    <child link="forearm_link"/>
    <origin xyz="-0.425 0 0" rpy="0 0 0"/>
    <axis xyz="0 0 1"/>
    <limit lower="-3.14159" upper="3.14159" effort="150.0" velocity="3.14159"/>
    <dynamics damping="0" friction="0"/>
  </joint>

  <joint name="wrist_1_joint" type="revolute">
    <parent link="forearm_link"/>
    <child link="wrist_1_link"/>
    <origin xyz="-0.39225 0 0.10915" rpy="0 0 0"/>
    <axis xyz="0 0 1"/>
    <limit lower="-6.2832" upper="6.2832" effort="28.0" velocity="3.14159"/>
    <dynamics damping="0" friction="0"/>
  </joint>

  <joint name="wrist_2_joint" type="revolute">
    <parent link="wrist_1_link"/>
    <child link="wrist_2_link"/>
    <origin xyz="0 -0.09465 0" rpy="1.570796327 0 0"/>
    <axis xyz="0 0 1"/>
    <limit lower="-6.2832" upper="6.2832" effort="28.0" velocity="3.14159"/>
    <dynamics damping="0" friction="0"/>
  </joint>

  <joint name="wrist_3_joint" type="revolute">
    <parent link="wrist_2_link"/>
    <child link="wrist_3_link"/>
    <origin xyz="0 0.0823 0" rpy="1.570796327 3.14159265 3.14159265"/>
    <axis xyz="0 0 1"/>
    <limit lower="-6.2832" upper="6.2832" effort="28.0" velocity="3.14159"/>
    <dynamics damping="0" friction="0"/>
  </joint>

  <joint name="tool_joint" type="fixed">
    <parent link="wrist_3_link"/>
    <child link="tool0"/>
    <origin xyz="0 0 0" rpy="0 0 0"/>
  </joint>

  <!-- ═══════════════════════════════════════════════════════════════
       ROS2_CONTROL — Gazebo bridge
  ═══════════════════════════════════════════════════════════════════ -->

  <ros2_control name="GazeboSystem" type="system">
    <hardware>
      <plugin>gazebo_ros2_control/GazeboSystem</plugin>
    </hardware>
    <joint name="shoulder_pan_joint">
      <command_interface name="position"/>
      <state_interface name="position"><param name="initial_value">0.0</param></state_interface>
      <state_interface name="velocity"/>
    </joint>
    <joint name="shoulder_lift_joint">
      <command_interface name="position"/>
      <state_interface name="position"><param name="initial_value">-1.5708</param></state_interface>
      <state_interface name="velocity"/>
    </joint>
    <joint name="elbow_joint">
      <command_interface name="position"/>
      <state_interface name="position"><param name="initial_value">0.0</param></state_interface>
      <state_interface name="velocity"/>
    </joint>
    <joint name="wrist_1_joint">
      <command_interface name="position"/>
      <state_interface name="position"><param name="initial_value">-1.5708</param></state_interface>
      <state_interface name="velocity"/>
    </joint>
    <joint name="wrist_2_joint">
      <command_interface name="position"/>
      <state_interface name="position"><param name="initial_value">0.0</param></state_interface>
      <state_interface name="velocity"/>
    </joint>
    <joint name="wrist_3_joint">
      <command_interface name="position"/>
      <state_interface name="position"><param name="initial_value">0.0</param></state_interface>
      <state_interface name="velocity"/>
    </joint>
  </ros2_control>

  <gazebo>
    <plugin filename="libgazebo_ros2_control.so" name="gazebo_ros2_control">
      <parameters>/home/algamal/ros2_ws/install/pick_scan_place/share/pick_scan_place/config/ros2_controllers.yaml</parameters>
    </plugin>
  </gazebo>

</robot>
